 
 -------------- celery@DESKTOP-83HRKM3 v5.2.7 (dawn-chorus)
--- ***** ----- 
-- ******* ---- Linux-5.10.60.1-microsoft-standard-WSL2-x86_64-with-glibc2.31 2023-05-06 17:19:51
- *** --- * --- 
- ** ---------- [config]
- ** ---------- .> app:         eam_backend:0x7f385c7171c0
- ** ---------- .> transport:   redis://172.17.0.2:6379/0
- ** ---------- .> results:     
- *** --- * --- .> concurrency: 8 (prefork)
-- ******* ---- .> task events: OFF (enable -E to monitor tasks in this worker)
--- ***** ----- 
 -------------- [queues]
                .> celery           exchange=celery(direct) key=celery
                

[tasks]
  . eam_backend.celery.debug_task

[2023-05-06 17:19:54,747: ERROR/MainProcess] consumer: Cannot connect to redis://172.17.0.2:6379/0: Error 113 connecting to 172.17.0.2:6379. No route to host..
Trying again in 2.00 seconds... (1/100)

[2023-05-06 17:19:57,867: ERROR/MainProcess] consumer: Cannot connect to redis://172.17.0.2:6379/0: Error 113 connecting to 172.17.0.2:6379. No route to host..
Trying again in 4.00 seconds... (2/100)

[2023-05-06 17:20:04,987: ERROR/MainProcess] consumer: Cannot connect to redis://172.17.0.2:6379/0: Error 113 connecting to 172.17.0.2:6379. No route to host..
Trying again in 6.00 seconds... (3/100)

[2023-05-06 17:20:14,107: ERROR/MainProcess] consumer: Cannot connect to redis://172.17.0.2:6379/0: Error 113 connecting to 172.17.0.2:6379. No route to host..
Trying again in 8.00 seconds... (4/100)

[2023-05-06 17:20:25,227: ERROR/MainProcess] consumer: Cannot connect to redis://172.17.0.2:6379/0: Error 113 connecting to 172.17.0.2:6379. No route to host..
Trying again in 10.00 seconds... (5/100)


worker: Warm shutdown (MainProcess)
 
 -------------- celery@DESKTOP-83HRKM3 v5.2.7 (dawn-chorus)
--- ***** ----- 
-- ******* ---- Linux-5.10.60.1-microsoft-standard-WSL2-x86_64-with-glibc2.31 2023-05-07 16:10:45
- *** --- * --- 
- ** ---------- [config]
- ** ---------- .> app:         eam_backend:0x7fc0e8c59340
- ** ---------- .> transport:   redis://redis-bughunters.app.secoder.net:6379/0
- ** ---------- .> results:     
- *** --- * --- .> concurrency: 8 (prefork)
-- ******* ---- .> task events: OFF (enable -E to monitor tasks in this worker)
--- ***** ----- 
 -------------- [queues]
                .> celery           exchange=celery(direct) key=celery
                

[tasks]
  . add_assets
  . eam_backend.celery.debug_task
  . test

[2023-05-07 16:12:59,795: ERROR/MainProcess] consumer: Cannot connect to redis://redis-bughunters.app.secoder.net:6379/0: Error 110 connecting to redis-bughunters.app.secoder.net:6379. Connection timed out..
Trying again in 2.00 seconds... (1/100)

[2023-05-07 16:15:12,916: ERROR/MainProcess] consumer: Cannot connect to redis://redis-bughunters.app.secoder.net:6379/0: Error 110 connecting to redis-bughunters.app.secoder.net:6379. Connection timed out..
Trying again in 4.00 seconds... (2/100)


worker: Warm shutdown (MainProcess)
 
 -------------- celery@DESKTOP-83HRKM3 v5.2.7 (dawn-chorus)
--- ***** ----- 
-- ******* ---- Linux-5.10.60.1-microsoft-standard-WSL2-x86_64-with-glibc2.31 2023-05-07 16:53:10
- *** --- * --- 
- ** ---------- [config]
- ** ---------- .> app:         eam_backend:0x7fa6a147b730
- ** ---------- .> transport:   redis://172.17.0.2:6379/0
- ** ---------- .> results:     
- *** --- * --- .> concurrency: 8 (prefork)
-- ******* ---- .> task events: OFF (enable -E to monitor tasks in this worker)
--- ***** ----- 
 -------------- [queues]
                .> celery           exchange=celery(direct) key=celery
                

[tasks]
  . add_assets
  . eam_backend.celery.debug_task
  . test

[2023-05-07 16:53:10,787: INFO/MainProcess] Connected to redis://172.17.0.2:6379/0
[2023-05-07 16:53:10,798: INFO/MainProcess] mingle: searching for neighbors
[2023-05-07 16:53:11,813: INFO/MainProcess] mingle: all alone
[2023-05-07 16:53:11,825: WARNING/MainProcess] /home/jasmine/miniconda3/envs/eam/lib/python3.9/site-packages/celery/fixups/django.py:203: UserWarning: Using settings.DEBUG leads to a memory
            leak, never use this setting in production environments!
  warnings.warn('''Using settings.DEBUG leads to a memory

[2023-05-07 16:53:11,825: INFO/MainProcess] celery@DESKTOP-83HRKM3 ready.
[2023-05-07 16:55:53,508: INFO/MainProcess] Task add_assets[9fa725c2-177f-4157-bbd7-0539fa827853] received
[2023-05-07 16:55:53,828: ERROR/ForkPoolWorker-7] Task add_assets[9fa725c2-177f-4157-bbd7-0539fa827853] raised unexpected: TypeError("check_length() missing 1 required positional argument: 'err_msg'")
Traceback (most recent call last):
  File "/home/jasmine/miniconda3/envs/eam/lib/python3.9/site-packages/celery/app/trace.py", line 451, in trace_task
    R = retval = fun(*args, **kwargs)
  File "/home/jasmine/miniconda3/envs/eam/lib/python3.9/site-packages/celery/app/trace.py", line 734, in __protected_call__
    return self.run(*args, **kwargs)
  File "/mnt/c/Users/86133/Desktop/eam-backend/eam_backend/async/tasks.py", line 32, in add_assets
    check_length(name, 0, 50, "assetName")
TypeError: check_length() missing 1 required positional argument: 'err_msg'
[2023-05-07 17:20:48,454: INFO/MainProcess] sync with celery@64eb49468d7f
[2023-05-07 17:21:01,194: INFO/MainProcess] Task test[874fef02-536c-477c-9e3a-acb1036229d4] received
[2023-05-07 17:21:02,115: WARNING/ForkPoolWorker-7] in
[2023-05-07 17:21:02,141: WARNING/ForkPoolWorker-7] Alice1
[2023-05-07 17:21:02,141: WARNING/ForkPoolWorker-7]  
[2023-05-07 17:21:02,141: WARNING/ForkPoolWorker-7] 874fef02-536c-477c-9e3a-acb1036229d4
[2023-05-07 17:21:07,244: WARNING/ForkPoolWorker-7] created username Alice1
[2023-05-07 17:21:07,276: INFO/ForkPoolWorker-7] Task test[874fef02-536c-477c-9e3a-acb1036229d4] succeeded in 5.881338354000036s: 'created username Alice1'
